Workbook

Sheet Costos Indirectos
B1: Costos
B2: Descripción | C2: Anual | D2: Mensual | E2: Costo/empleado | H2: Empleados | I2: 4
B4: Renta | C4: 250000 | D4: =+C4/12 -> 20833.333 | E4: =+D4/$I$2 -> 5208.3333
B5: Luz | C5: 36000 | D5: =+C5/12 -> 3000 | E5: =+D5/$I$2 -> 750
B6: Agua | C6: 12000 | D6: =+C6/12 -> 1000 | E6: =+D6/$I$2 -> 250
B7: Limpieza | C7: 55000 | D7: =+C7/12 -> 4583.3333 | E7: =+D7/$I$2 -> 1145.8333
B8: Papelería | C8: 18000 | D8: =+C8/12 -> 1500 | E8: =+D8/$I$2 -> 375
B9: Varios | C9: 24000 | D9: =+C9/12 -> 2000 | E9: =+D9/$I$2 -> 500
B10: Caja | C10: 12000 | D10: =+C10/12 -> 1000 | E10: =+D10/$I$2 -> 250
B19: Total | C19: =SUM(C4:C18) -> 407000 | D19: =SUM(D4:D18) -> 33916.667 | E19: =+D19/$I$2 -> 8479.1667

Sheet Hw&SW
B1: Infraestructura
B2: Descripción | C2: Número | D2: Costo Unitario | E2: Costo por proyecto | I2: Número de meses de duración | J2: 12
B3: Laptop Pavilion HP | C3: 4 | D3: 18000 | E3: =+D3/$J$2 -> 1500 | I3: Empleados proyecto | J3: 4
B4: Apple - MacBook Pro de 13" - Core i5 - Iris Plus 655 - Memoria de 8GB - SSD de 256GB | C4: 1 | D4: 39000 | E4: =+D4/$J$2 -> 3250
B5: Laptop Dell | E5: =+D5/$J$2 -> 0
B6: Dell - Laptop INSPIRON 5584 I5 de 15.6" - Core i5 - GeForce MX130 - Memoria 8GB | C6: 3 | D6: 22000 | E6: =+D6/$J$2 -> 1833.3333
B7: Amazon Cloud | C7: 1 | D7: =500*20 -> 10000 | E7: =+D7*$J$2 -> 120000
B8: Ofiice 365 | C8: =+$J$3 -> 4 | D8: 980 | E8: =+D8*$C$8/$J$2 -> 326.66667
B9: Visual Studio | C9: =+$J$3 -> 4 | D9: 1199 | E9: =+D9*$C$8/$J$2 -> 399.66667
B16: Totales | E16: =SUM(E3:E15) -> 127309.67

Sheet Sueldos
B2: Sueldos
B3: Puesto | C3: Mensual | D3: Recursos Proyecto | E3: Total Mensual | F3: Total Proyecto | G3: Tiempo a Utilizar
B4: Analista | C4: =+DistribuciónEsfuerzo!J18 -> 25000 | D4: 1 | E4: =+D4*C4 -> 25000 | F4: =+E4*G4 -> 69427.494 | G4: =+DistribuciónEsfuerzo!I18 -> 2.7770998
B5: Diseñador | C5: =+DistribuciónEsfuerzo!J30 -> 30000 | D5: 1 | E5: =+D5*C5 -> 30000 | F5: =+E5*G5 -> 66650.394 | G5: =+DistribuciónEsfuerzo!I30 -> 2.2216798
B6: Arquitecto SW | C6: 35000 | D6: 0 | E6: =+D6*C6 -> 0 | F6: =+E6*G6 -> 0 | G6: 0
B7: Programador | C7: =+DistribuciónEsfuerzo!J41 -> 40000 | D7: 1 | E7: =+D7*C7 -> 40000 | F7: =+E7*G7 -> 155517.59 | G7: =+DistribuciónEsfuerzo!I41 -> 3.8879397
B8: Tester | C8: =+DistribuciónEsfuerzo!J52 -> 20000 | D8: 1 | E8: =+D8*C8 -> 20000 | F8: =+E8*G8 -> 44433.596 | G8: =+DistribuciónEsfuerzo!I52 -> 2.2216798
B9: Dirección Proyecto | C9: 33000 | D9: 0 | E9: =+D9*C9 -> 0 | F9: =+E9*G9 -> 0 | G9: 0
B10: Scrum Master | C10: 32000 | D10: 0 | E10: =+D10*C10 -> 0 | F10: =+E10*G10 -> 0 | G10: 0
B11: Implementador | C11: 15000 | D11: 0 | E11: =+D11*C11 -> 0 | F11: =+E11*G11 -> 0 | G11: 0
B12: Change Management | C12: 20000 | D12: 0 | E12: =+D12*C12 -> 0 | F12: =+E12*G12 -> 0 | G12: 0
B13: DBA | C13: 30000 | D13: 0 | E13: =+D13*C13 -> 0 | F13: =+E13*G13 -> 0 | G13: 0
B18: Totales | F18: =+DistribuciónEsfuerzo!B15 -> 1344116.3

Sheet Otros
B2: Otros Costos
B3: Descripción | C3: Nùmero | D3: Costo | E3: Total
B4: Viaje 1 | C4: 0 | D4: 1200 | E4: =+D4*C4 -> 0
B5: Viaje 2 | C5: 0 | D5: 1200 | E5: =+D5*C5 -> 0
B10: Totales | E10: =SUM(E4:E9) -> 0

Sheet TotalProyecto
B2: Resumen Costos
B3: Descripciòn | C3: Costo | D3: % | E3: Tiempo
B4: Indirectos | C4: =+'Costos Indirectos'!E19*'Hw&SW'!J3*'Hw&SW'!J2 -> 407000
B5: Infraestructura | C5: =+'Hw&SW'!E16 -> 127309.67
B6: Sueldos | C6: =+Sueldos!F18 -> 1344116.3
B7: Otros | C7: =+Otros!E10 -> 0
B8: Total Proyecto | C8: =SUM(C4:C6) -> 1878426
B9: Ganancia | C9: =+D9*C8 -> 563527.79 | D9: 0.3
B10: Total Propuesto | C10: =+C9+C8 -> 2441953.7 | E10: =+DistribuciónEsfuerzo!C23 -> 32.214357

Sheet UUCP
A1: ESTIMACIÓN DE ESFUERZO
A3: Factor de Peso Actores | B3: Descripción | C3: Peso | D3: Número | E3: Valor ponderado | F3: Comentario
A4: Simple | B4: API Programa | C4: 1 | D4: 2 | E4: =C4*D4 -> 2
A5: Intermedio | B5: WS | C5: 2 | D5: 0 | E5: =C5*D5 -> 0
A6: Complejo | B6: Humano con GUI | C6: 3 | D6: 5 | E6: =C6*D6 -> 15
A7: Peso Total Actores | E7: =SUM(E4:E6) -> 17
A9: Factor de Peso Casos de Uso (Basado en el número de transacciones en el CU) | C9: Peso | D9: Número | E9: Valor ponderado | F9: Comentario
A10: Simple | B10: 3 ó menos escenarios | C10: 5 | D10: 0 | E10: =C10*D10 -> 0
A11: Intermedio | B11: 4 a 7 escenarios | C11: 10 | D11: 9 | E11: =C11*D11 -> 90
A12: Complejo | B12: más de 7 escenarios | C12: 15 | D12: 6 | E12: =C12*D12 -> 90
A13: Factores Basados en Transacciones | E13: =SUM(E10:E12) -> 180
A15: Puntos de CU No Ajustados | E15: =E7+E13 -> 197
A17: Factores de Peso Técnicos | B17: Escala de asignación | C17: Peso | D17: Número | E17: Valor ponderado | F17: Razón
A18: T1 Sistema Distribuido | B18: 0=no importante 5=esencial | C18: 2 | D18: 3 | E18: =C18*D18 -> 6 | F18: REST y GraphQL como servicios independientes sobre la misma BD, integración con España y expansión a más sedes.
A19: T2 Objetivos de Desempeño o Tiempo de Respuesta | B19: 0=no importante 5=esencial | C19: 1 | D19: 4 | E19: =C19*D19 -> 4 | F19: Apartado de clase con límite estricto de 5 minutos y alto volumen de alumnos concurrentes.
A20: T3 Eficiencia Usuario Final (online) | B20: 0=no importante 5=esencial | C20: 1 | D20: 5 | E20: =C20*D20 -> 5 | F20: Diseño intuitivo y responsivo con ayuda en línea en todos los campos, requisito explícito del problema.
A21: T4 Procesamiento Interno Complejo | B21: 0=no importante 5=esencial | C21: 1 | D21: 4 | E21: =C21*D21 -> 4 | F21: Reglas de negocio complejas: precios variables, descuentos, penalizaciones, calificación automática, transferencia del 10%.
A22: T5 Código Debe Ser Reusable | B22: 0=no importante 5=esencial | C22: 1 | D22: 3 | E22: =C22*D22 -> 3 | F22: Soporte genérico para cualquier idioma y nivel dado de alta.
A23: T6 Facilidad de Instalación | B23: 0=no importante 5=esencial | C23: 0.5 | D23: 2 | E23: =C23*D23 -> 1 | F23: Contenedorización (Docker) para instalación consistente.
A24: T7 Facilidad de Uso | B24: 0=no importante 5=esencial | C24: 0.5 | D24: 5 | E24: =C24*D24 -> 2.5 | F24: Requisito explícito: diseño intuitivo, sin necesidad de capacitación.
A25: T8 Portabilidad | B25: 0=no importante 5=esencial | C25: 2 | D25: 4 | E25: =C25*D25 -> 8 | F25: Arquitectura con servicios independientes pensada para escalar a más edificios y sedes.
A26: T9 Facilidad de Cambio | B26: 0=no importante 5=esencial | C26: 1 | D26: 4 | E26: =C26*D26 -> 4 | F26: Idiomas, niveles, precios y exámenes configurables sin tocar código.
A27: T10 Concurrencia | B27: 0=no importante 5=esencial | C27: 1 | D27: 5 | E27: =C27*D27 -> 5 | F27: Alta concurrencia esperada en agendado de sesiones y disponibilidad de salones en tiempo real.
A28: T11 Incluye Características Especiales de Seguridad | B28: 0=no importante 5=esencial | C28: 1 | D28: 5 | E28: =C28*D28 -> 5 | F28: Datos sensibles: tarjetas de crédito, CLABE de profesores, credenciales de acceso.
A29: T12 Provee Acceso Directo a Terceros | B29: 0=no importante 5=esencial | C29: 1 | D29: 4 | E29: =C29*D29 -> 4 | F29: Servicios REST y GraphQL públicos, más web service con corporativo de España.
A30: T13 Se Requieren Ayudas Especiales de Entrenamiento de Usuarios | B30: 0=no importante 5=esencial | C30: 1 | D30: 4 | E30: =C30*D30 -> 4 | F30: Ayuda en línea exigida en todos los campos para evitar capacitación formal.
A31: Factores Técnicos | E31: =SUM(E18:E30) -> 55.5
A32: Factor de Complejidad Técnica (TCF) | B32: .06 + (.01*Factor Técnico) | E32: =0.06+(0.01*E31) -> 0.615
A34: Factores de Peso Ambientales del Equipo | B34: Escala de 0 a 5 | C34: Peso | D34: Número | E34: Valor ponderado | F34: Razón | G34: Experiencia/Estabilidad
A35: F1 Familiaridad con un Proceso Definido (RUP) | B35: 0 = sin experiencia, 3=media, 5=experto | C35: 1.5 | D35: 3 | E35: =C35*D35 -> 4.5 | G35: =IF(E35<3,1,0) -> 0
A36: F2 Experiencia en el Dominio de Aplicación | B36: 0 = sin experiencia, 3=media, 5=experto | C36: 0.5 | D36: 2 | E36: =C36*D36 -> 1 | G36: =IF(E36<3,1,0) -> 1
A37: F3 Experiencia en Orientación a Objetos | B37: 0 = sin experiencia, 3=media, 5=experto | C37: 1 | D37: 4 | E37: =C37*D37 -> 4 | G37: =IF(E37<3,1,0) -> 0
A38: F4 Capacidad de Liderazgo de Analistas | B38: 0 = sin experiencia, 3=media, 5=experto | C38: 0.5 | D38: 4 | E38: =C38*D38 -> 2 | G38: =IF(E38<3,1,0) -> 1
A39: F5 Motivación | B39: 0=sin, 3=media, 5=alta | C39: 1 | D39: 5 | E39: =C39*D39 -> 5 | G39: =IF(E39<3,1,0) -> 0
A40: F6 Requerimientos Estables | B40: 0=extremadamente inestable, 5=no cambian | C40: 2 | D40: 4 | E40: =C40*D40 -> 8 | G40: =IF(E40<3,1,0) -> 0
A41: F7 Miembros a Tiempo Parcial | B41: 0=tiempo parcial, 5=tiempo completo | C41: -1 | D41: 2 | E41: =C41*D41 -> -2 | G41: =IF(E41>3,1,0) -> 0
A42: F8 Dificultad del Lenguaje de Programación | B42: 0=fácil, 3=medio,5=difícil | C42: -1 | D42: 3 | E42: =C42*D42 -> -3 | G42: =IF(E42>3,1,0) -> 0
A43: Factores Ambientales | E43: =SUM(E35:E42) -> 19.5 | G43: =SUM(G35:G42) -> 2
A44: EFactor | B44: 1.4 + (-0.03*Factor Ambiental) | E44: =1.4 + (-0.03*E43) -> 0.815
A46: Puntos de Casos de Uso Ajustados | E46: =E15 * E32 *E44 -> 98.741325
...

Sheet DistribuciónEsfuerzo
A1: Distribución de esfuerzo
A2: Etapa | B2: Ponderación | C2: Horas Hombre | E2: Horas Hombre Totales | F2: Horas Mes | G2: Meses | H2: Personas En Equipo | I2: Total Meses
A3: Análisis | B3: 0.25 | C3: =+C7*B3 -> 1777.3438 | E3: =+$C$7 -> 7109.3754 | F3: 160 | G3: =+E3/F3 -> 44.433596 | H3: 2 | I3: =+G3/H3 -> 22.216798
A4: Diseño | B4: 0.2 | C4: =+C7*B4 -> 1421.8751 | E4: =+$C$7 -> 7109.3754 | F4: 160 | G4: =+E4/F4 -> 44.433596 | H4: 3 | I4: =+G4/H4 -> 14.811199
A5: Programación | B5: 0.35 | C5: =+C7*B5 -> 2488.2814 | E5: =+$C$7 -> 7109.3754 | F5: 160 | G5: =+E5/F5 -> 44.433596 | H5: 4 | I5: =+G5/H5 -> 11.108399
A6: Test | B6: 0.2 | C6: =+C7*B6 -> 1421.8751 | E6: =+$C$7 -> 7109.3754 | F6: 160 | G6: =+E6/F6 -> 44.433596 | H6: 5 | I6: =+G6/H6 -> 8.8867193
A7: Total | B7: =SUM(B3:B6) -> 1 | C7: =+UUCP!E50 -> 7109.3754 | E7: =+$C$7 -> 7109.3754 | F7: 160 | G7: =+E7/F7 -> 44.433596 | H7: 6 | I7: =+G7/H7 -> 7.4055994
E8: =+$C$7 -> 7109.3754 | F8: 160 | G8: =+E8/F8 -> 44.433596 | H8: 7 | I8: =+G8/H8 -> 6.3476566
A9: Costo | E9: =+$C$7 -> 7109.3754 | F9: 160 | G9: =+E9/F9 -> 44.433596 | H9: 8 | I9: =+G9/H9 -> 5.5541995
A10: Etapa | B10: Sueldo | E10: =+$C$7 -> 7109.3754 | F10: 160 | G10: =+E10/F10 -> 44.433596 | H10: 9 | I10: =+G10/H10 -> 4.9370662
A11: Análisis | B11: =+K18 -> 277709.98
A12: Diseño | B12: =+K30 -> 266601.58
A13: Programación | B13: =+K41 -> 622070.35 | E13: Análisis
A14: Test | B14: =+K52 -> 177734.39 | E14: Horas Hombre Totales | F14: Horas Mes | G14: Meses | H14: Personas En Equipo | I14: Total Meses | J14: Costo Analista | K14: Costo Total
A15: Total | B15: =SUM(B11:B14) -> 1344116.3 | E15: =+$C$3 -> 1777.3438 | F15: 160 | G15: =+E15/F15 -> 11.108399 | H15: 1 | I15: =+G15/H15 -> 11.108399 | J15: 25000 | K15: =+J15*H15*I15 -> 277709.98
E16: =+$C$3 -> 1777.3438 | F16: 160 | G16: =+E16/F16 -> 11.108399 | H16: 2 | I16: =+G16/H16 -> 5.5541995 | J16: 25000 | K16: =+J16*H16*I16 -> 277709.98
A17: Recursos | E17: =+$C$3 -> 1777.3438 | F17: 160 | G17: =+E17/F17 -> 11.108399 | H17: 3 | I17: =+G17/H17 -> 3.7027997 | J17: 25000 | K17: =+J17*H17*I17 -> 277709.98
A18: Etapa | B18: Número | C18: Tiempo | E18: =+$C$3 -> 1777.3438 | F18: 160 | G18: =+E18/F18 -> 11.108399 | H18: 4 | I18: =+G18/H18 -> 2.7770998 | J18: 25000 | K18: =+J18*H18*I18 -> 277709.98
A19: Análisis | B19: =+H15 -> 1 | C19: =+I15 -> 11.108399 | E19: =+$C$3 -> 1777.3438 | F19: 160 | G19: =+E19/F19 -> 11.108399 | H19: 5 | I19: =+G19/H19 -> 2.2216798 | J19: 25000 | K19: =+J19*H19*I19 -> 277709.98
A20: Diseño | B20: =+H27 -> 1 | C20: =+I27 -> 8.8867193 | E20: =+$C$3 -> 1777.3438 | F20: 160 | G20: =+E20/F20 -> 11.108399 | H20: 6 | I20: =+G20/H20 -> 1.8513998 | J20: 25000 | K20: =+J20*H20*I20 -> 277709.98
A21: Programación | B21: =+H39 -> 2 | C21: =+I39 -> 7.7758793 | E21: =+$C$3 -> 1777.3438 | F21: 160 | G21: =+E21/F21 -> 11.108399 | H21: 7 | I21: =+G21/H21 -> 1.5869142 | J21: 25000 | K21: =+J21*H21*I21 -> 277709.98
A22: Test | B22: =+H50 -> 2 | C22: =+I50 -> 4.4433596 | E22: =+$C$3 -> 1777.3438 | F22: 160 | G22: =+E22/F22 -> 11.108399 | H22: 8 | I22: =+G22/H22 -> 1.3885499 | J22: 25000 | K22: =+J22*H22*I22 -> 277709.98
A23: Total | B23: =SUM(B19:B22) -> 6 | C23: =SUM(C19:C22) -> 32.214357 | E23: =+$C$3 -> 1777.3438 | F23: 160 | G23: =+E23/F23 -> 11.108399 | H23: 9 | I23: =+G23/H23 -> 1.2342666 | J23: 25000 | K23: =+J23*H23*I23 -> 277709.98
E25: Diseño
E26: Horas Hombre Totales | F26: Horas Mes | G26: Meses | H26: Personas En Equipo | I26: Total Meses | J26: Costo Diseñador | K26: Costo Total
E27: =+$C$4 -> 1421.8751 | F27: 160 | G27: =+E27/F27 -> 8.8867193 | H27: 1 | I27: =+G27/H27 -> 8.8867193 | J27: 30000 | K27: =+J27*H27*I27 -> 266601.58
E28: =+$C$4 -> 1421.8751 | F28: 160 | G28: =+E28/F28 -> 8.8867193 | H28: 2 | I28: =+G28/H28 -> 4.4433596 | J28: 30000 | K28: =+J28*H28*I28 -> 266601.58
E29: =+$C$4 -> 1421.8751 | F29: 160 | G29: =+E29/F29 -> 8.8867193 | H29: 3 | I29: =+G29/H29 -> 2.9622398 | J29: 30000 | K29: =+J29*H29*I29 -> 266601.58
E30: =+$C$4 -> 1421.8751 | F30: 160 | G30: =+E30/F30 -> 8.8867193 | H30: 4 | I30: =+G30/H30 -> 2.2216798 | J30: 30000 | K30: =+J30*H30*I30 -> 266601.58
E31: =+$C$4 -> 1421.8751 | F31: 160 | G31: =+E31/F31 -> 8.8867193 | H31: 5 | I31: =+G31/H31 -> 1.7773439 | J31: 30000 | K31: =+J31*H31*I31 -> 266601.58
E32: =+$C$4 -> 1421.8751 | F32: 160 | G32: =+E32/F32 -> 8.8867193 | H32: 6 | I32: =+G32/H32 -> 1.4811199 | J32: 30000 | K32: =+J32*H32*I32 -> 266601.58
E33: =+$C$4 -> 1421.8751 | F33: 160 | G33: =+E33/F33 -> 8.8867193 | H33: 7 | I33: =+G33/H33 -> 1.2695313 | J33: 30000 | K33: =+J33*H33*I33 -> 266601.58
E34: =+$C$4 -> 1421.8751 | F34: 160 | G34: =+E34/F34 -> 8.8867193 | H34: 8 | I34: =+G34/H34 -> 1.1108399 | J34: 30000 | K34: =+J34*H34*I34 -> 266601.58
E35: =+$C$4 -> 1421.8751 | F35: 160 | G35: =+E35/F35 -> 8.8867193 | H35: 9 | I35: =+G35/H35 -> 0.98741325 | J35: 30000 | K35: =+J35*H35*I35 -> 266601.58
E37: Programación
E38: Horas Hombre Totales | F38: Horas Mes | G38: Meses | H38: Personas En Equipo | I38: Total Meses | J38: Costo Programador | K38: Costo Total
E39: =+$C$5 -> 2488.2814 | F39: 160 | G39: =+E39/F39 -> 15.551759 | H39: 2 | I39: =+G39/H39 -> 7.7758793 | J39: 40000 | K39: =+J39*H39*I39 -> 622070.35
E40: =+$C$5 -> 2488.2814 | F40: 160 | G40: =+E40/F40 -> 15.551759 | H40: 3 | I40: =+G40/H40 -> 5.1839196 | J40: 40000 | K40: =+J40*H40*I40 -> 622070.35
E41: =+$C$5 -> 2488.2814 | F41: 160 | G41: =+E41/F41 -> 15.551759 | H41: 4 | I41: =+G41/H41 -> 3.8879397 | J41: 40000 | K41: =+J41*H41*I41 -> 622070.35
E42: =+$C$5 -> 2488.2814 | F42: 160 | G42: =+E42/F42 -> 15.551759 | H42: 5 | I42: =+G42/H42 -> 3.1103517 | J42: 40000 | K42: =+J42*H42*I42 -> 622070.35
...
